Workbook
Name Slicer_Age1: #N/A

Sheet Dashboard
B2: U.S. VOTERS 2012 · PARTICIPATION DASHBOARD
B4: From population to ballot: citizens → registered → confirmed voters, by age group and by state
B6: CITIZENS | F6: REGISTERED | J6: CONFIRMED VOTERS | N6: REGISTRATION RATE | R6: TURNOUT (OF REGISTERED) | V6: VOTER PENETRATION
B7: =Analysis!B5 -> 215085000 | F7: =Analysis!C5 -> 153153000 | J7: =Analysis!D5 -> 132952000 | N7: =Analysis!E5 -> 0.71205802 | R7: =Analysis!F5 -> 0.86809922 | V7: =Analysis!G5 -> 0.56515437
R42: KEY INSIGHTS
R43: =Analysis!A73 -> Highest-turnout age group: 65+ at 90.7% vs 18 to 24 at 76.9%
R46: =Analysis!A74 -> Largest share of confirmed voters: 45 to 64 (39.1%)
R49: =Analysis!A75 -> Top turnout state: Colorado (94.7%); biggest registration gap: California (8.1M citizens unregistered)
R52: =Analysis!A76 -> Most confirmed voters: California (13.5M); highest penetration: Mississippi (73.3%)
R55: =Analysis!A77 -> National: 71.2% of citizens registered, 86.8% of registered confirmed, 56.5% of total population confirmed

Sheet Analysis
A1: ANALYSIS · U.S. Voters 2012 (all figures are live formulas on the data sheet)
A3: KPIs
A4: Total Pop. | B4: Citizens | C4: Registered | D4: Confirmed | E4: Registration Rate | F4: Turnout Rate | G4: Voter Penetration
A5: =SUM('U.S. Voters (2012)'!$C$2:$C$256) -> 235249000 | B5: =SUM('U.S. Voters (2012)'!$D$2:$D$256) -> 215085000 | C5: =SUM('U.S. Voters (2012)'!$E$2:$E$256) -> 153153000 | D5: =SUM('U.S. Voters (2012)'!$F$2:$F$256) -> 132952000 | E5: =C5/B5 -> 0.71205802 | F5: =D5/C5 -> 0.86809922 | G5: =D5/A5 -> 0.56515437
A7: Age-group participation (Q1, Q4, Q6)
A8: Age | B8: Total Pop. | C8: Citizens | D8: Registered | E8: Confirmed | F8: Registration Rate | G8: Turnout Rate | H8: Voter Penetration | I8: Share of Confirmed
A9: 18 to 24 | B9: =SUMIFS('U.S. Voters (2012)'!$C$2:$C$256,'U.S. Voters (2012)'!$B$2:$B$256,$A9) -> 29881000 | C9: =SUMIFS('U.S. Voters (2012)'!$D$2:$D$256,'U.S. Voters (2012)'!$B$2:$B$256,$A9) -> 27537000 | D9: =SUMIFS('U.S. Voters (2012)'!$E$2:$E$256,'U.S. Voters (2012)'!$B$2:$B$256,$A9) -> 14767000 | E9: =SUMIFS('U.S. Voters (2012)'!$F$2:$F$256,'U.S. Voters (2012)'!$B$2:$B$256,$A9) -> 11351000 | F9: =D9/C9 -> 0.5362603 | G9: =E9/D9 -> 0.76867339 | H9: =E9/B9 -> 0.3798735 | I9: =E9/$E$14 -> 0.085376677
A10: 25 to 34 | B10: =SUMIFS('U.S. Voters (2012)'!$C$2:$C$256,'U.S. Voters (2012)'!$B$2:$B$256,$A10) -> 41145000 | C10: =SUMIFS('U.S. Voters (2012)'!$D$2:$D$256,'U.S. Voters (2012)'!$B$2:$B$256,$A10) -> 35474000 | D10: =SUMIFS('U.S. Voters (2012)'!$E$2:$E$256,'U.S. Voters (2012)'!$B$2:$B$256,$A10) -> 23436000 | E10: =SUMIFS('U.S. Voters (2012)'!$F$2:$F$256,'U.S. Voters (2012)'!$B$2:$B$256,$A10) -> 18978000 | F10: =D10/C10 -> 0.66065287 | G10: =E10/D10 -> 0.80977983 | H10: =E10/B10 -> 0.46124681 | I10: =E10/$E$14 -> 0.14274325
A11: 35 to 44 | B11: =SUMIFS('U.S. Voters (2012)'!$C$2:$C$256,'U.S. Voters (2012)'!$B$2:$B$256,$A11) -> 39624000 | C11: =SUMIFS('U.S. Voters (2012)'!$D$2:$D$256,'U.S. Voters (2012)'!$B$2:$B$256,$A11) -> 34266000 | D11: =SUMIFS('U.S. Voters (2012)'!$E$2:$E$256,'U.S. Voters (2012)'!$B$2:$B$256,$A11) -> 24458000 | E11: =SUMIFS('U.S. Voters (2012)'!$F$2:$F$256,'U.S. Voters (2012)'!$B$2:$B$256,$A11) -> 20965000 | F11: =D11/C11 -> 0.71376875 | G11: =E11/D11 -> 0.85718374 | H11: =E11/B11 -> 0.52909853 | I11: =E11/$E$14 -> 0.15768849
A12: 45 to 64 | B12: =SUMIFS('U.S. Voters (2012)'!$C$2:$C$256,'U.S. Voters (2012)'!$B$2:$B$256,$A12) -> 82085000 | C12: =SUMIFS('U.S. Voters (2012)'!$D$2:$D$256,'U.S. Voters (2012)'!$B$2:$B$256,$A12) -> 76641000 | D12: =SUMIFS('U.S. Voters (2012)'!$E$2:$E$256,'U.S. Voters (2012)'!$B$2:$B$256,$A12) -> 57797000 | E12: =SUMIFS('U.S. Voters (2012)'!$F$2:$F$256,'U.S. Voters (2012)'!$B$2:$B$256,$A12) -> 52013000 | F12: =D12/C12 -> 0.75412638 | G12: =E12/D12 -> 0.8999256 | H12: =E12/B12 -> 0.63364805 | I12: =E12/$E$14 -> 0.39121638
A13: 65+ | B13: =SUMIFS('U.S. Voters (2012)'!$C$2:$C$256,'U.S. Voters (2012)'!$B$2:$B$256,$A13) -> 42514000 | C13: =SUMIFS('U.S. Voters (2012)'!$D$2:$D$256,'U.S. Voters (2012)'!$B$2:$B$256,$A13) -> 41167000 | D13: =SUMIFS('U.S. Voters (2012)'!$E$2:$E$256,'U.S. Voters (2012)'!$B$2:$B$256,$A13) -> 32695000 | E13: =SUMIFS('U.S. Voters (2012)'!$F$2:$F$256,'U.S. Voters (2012)'!$B$2:$B$256,$A13) -> 29645000 | F13: =D13/C13 -> 0.7942041 | G13: =E13/D13 -> 0.90671356 | H13: =E13/B13 -> 0.69729971 | I13: =E13/$E$14 -> 0.22297521
A14: Total | B14: =SUM(B9:B13) -> 235249000 | C14: =SUM(C9:C13) -> 215085000 | D14: =SUM(D9:D13) -> 153153000 | E14: =SUM(E9:E13) -> 132952000 | F14: =D14/C14 -> 0.71205802 | G14: =E14/D14 -> 0.86809922 | H14: =E14/B14 -> 0.56515437 | I14: =SUM(I9:I13) -> 1
R16: Leaderboards
A17: State-level metrics (Q2, Q3, Q5, Q7, Q8) | R17: Top 10 Turnout (Q2) | U17: Top 10 Citizen–Registered Gap (Q3) | X17: Top 10 Confirmed Voters (Q5) | AB17: Top 10 Voter Penetration (Q8) | AE17: High registration, lowest turnout (Q7)
A18: State | B18: Total Pop. | C18: Citizens | D18: Registered | E18: Confirmed | F18: Registration Rate | G18: Turnout Rate | H18: Voter Penetration | I18: Citizen–Registered Gap | J18: Gap % of Citizens | K18: Rank: Turnout | L18: Rank: Gap | M18: Rank: Confirmed | N18: Rank: Penetration | O18: Q7 Score | P18: Rank: Q7 | R18: State | S18: Turnout | U18: State | V18: Gap | X18: State | Y18: Confirmed | Z18: Total Pop. | AB18: State | AC18: Penetration | AE18: State | AF18: Reg. Rate | AG18: Turnout
A19: Alabama | B19: =SUMIFS('U.S. Voters (2012)'!$C$2:$C$256,'U.S. Voters (2012)'!$A$2:$A$256,$A19) -> 3594000 | C19: =SUMIFS('U.S. Voters (2012)'!$D$2:$D$256,'U.S. Voters (2012)'!$A$2:$A$256,$A19) -> 3480000 | D19: =SUMIFS('U.S. Voters (2012)'!$E$2:$E$256,'U.S. Voters (2012)'!$A$2:$A$256,$A19) -> 2555000 | E19: =SUMIFS('U.S. Voters (2012)'!$F$2:$F$256,'U.S. Voters (2012)'!$A$2:$A$256,$A19) -> 2154000 | F19: =D19/C19 -> 0.7341954 | G19: =E19/D19 -> 0.84305284 | H19: =E19/B19 -> 0.59933222 | I19: =C19-D19 -> 925000 | J19: =I19/C19 -> 0.2658046 | K19: =COUNTIF($G$19:$G$69,">"&G19)+COUNTIF($G$19:G19,G19) -> 42 | L19: =COUNTIF($I$19:$I$69,">"&I19)+COUNTIF($I$19:I19,I19) -> 22 | M19: =COUNTIF($E$19:$E$69,">"&E19)+COUNTIF($E$19:E19,E19) -> 24 | N19: =COUNTIF($H$19:$H$69,">"&H19)+COUNTIF($H$19:H19,H19) -> 25 | O19: =IF(F19>=MEDIAN($F$19:$F$69),G19,2) -> 0.84305284 | P19: =COUNTIF($O$19:$O$69,"<"&O19)+COUNTIF($O$19:O19,O19) -> 3 | R19: =INDEX($A$19:$A$69,MATCH(1,$K$19:$K$69,0)) -> Colorado | S19: =INDEX($G$19:$G$69,MATCH(1,$K$19:$K$69,0)) -> 0.94686907 | U19: =INDEX($A$19:$A$69,MATCH(1,$L$19:$L$69,0)) -> California | V19: =INDEX($I$19:$I$69,MATCH(1,$L$19:$L$69,0)) -> 8062000 | X19: =INDEX($A$19:$A$69,MATCH(1,$M$19:$M$69,0)) -> California | Y19: =INDEX($E$19:$E$69,MATCH(1,$M$19:$M$69,0)) -> 13463000 | Z19: =INDEX($B$19:$B$69,MATCH(1,$M$19:$M$69,0)) -> 28358000 | AB19: =INDEX($A$19:$A$69,MATCH(1,$N$19:$N$69,0)) -> Mississippi | AC19: =INDEX($H$19:$H$69,MATCH(1,$N$19:$N$69,0)) -> 0.73281034 | AE19: =INDEX($A$19:$A$69,MATCH(1,$P$19:$P$69,0)) -> South Dakota | AF19: =INDEX($F$19:$F$69,MATCH(1,$P$19:$P$69,0)) -> 0.74917492 | AG19: =INDEX($G$19:$G$69,MATCH(1,$P$19:$P$69,0)) -> 0.81718062
A20: Alaska | B20: =SUMIFS('U.S. Voters (2012)'!$C$2:$C$256,'U.S. Voters (2012)'!$A$2:$A$256,$A20) -> 516000 | C20: =SUMIFS('U.S. Voters (2012)'!$D$2:$D$256,'U.S. Voters (2012)'!$A$2:$A$256,$A20) -> 495000 | D20: =SUMIFS('U.S. Voters (2012)'!$E$2:$E$256,'U.S. Voters (2012)'!$A$2:$A$256,$A20) -> 360000 | E20: =SUMIFS('U.S. Voters (2012)'!$F$2:$F$256,'U.S. Voters (2012)'!$A$2:$A$256,$A20) -> 289000 | F20: =D20/C20 -> 0.72727273 | G20: =E20/D20 -> 0.80277778 | H20: =E20/B20 -> 0.56007752 | I20: =C20-D20 -> 135000 | J20: =I20/C20 -> 0.27272727 | K20: =COUNTIF($G$19:$G$69,">"&G20)+COUNTIF($G$19:G20,G20) -> 49 | L20: =COUNTIF($I$19:$I$69,">"&I20)+COUNTIF($I$19:I20,I20) -> 48 | M20: =COUNTIF($E$19:$E$69,">"&E20)+COUNTIF($E$19:E20,E20) -> 50 | N20: =COUNTIF($H$19:$H$69,">"&H20)+COUNTIF($H$19:H20,H20) -> 38 | O20: =IF(F20>=MEDIAN($F$19:$F$69),G20,2) -> 2 | P20: =COUNTIF($O$19:$O$69,"<"&O20)+COUNTIF($O$19:O20,O20) -> 27 | R20: =INDEX($A$19:$A$69,MATCH(2,$K$19:$K$69,0)) -> Wisconsin | S20: =INDEX($G$19:$G$69,MATCH(2,$K$19:$K$69,0)) -> 0.94273659 | U20: =INDEX($A$19:$A$69,MATCH(2,$L$19:$L$69,0)) -> Texas | V20: =INDEX($I$19:$I$69,MATCH(2,$L$19:$L$69,0)) -> 5312000 | X20: =INDEX($A$19:$A$69,MATCH(2,$M$19:$M$69,0)) -> Texas | Y20: =INDEX($E$19:$E$69,MATCH(2,$M$19:$M$69,0)) -> 8643000 | Z20: =INDEX($B$19:$B$69,MATCH(2,$M$19:$M$69,0)) -> 18642000 | AB20: =INDEX($A$19:$A$69,MATCH(2,$N$19:$N$69,0)) -> Wisconsin | AC20: =INDEX($H$19:$H$69,MATCH(2,$N$19:$N$69,0)) -> 0.71891519 | AE20: =INDEX($A$19:$A$69,MATCH(2,$P$19:$P$69,0)) -> Missouri | AF20: =INDEX($F$19:$F$69,MATCH(2,$P$19:$P$69,0)) -> 0.76729417 | AG20: =INDEX($G$19:$G$69,MATCH(2,$P$19:$P$69,0)) -> 0.83298847
A21: Arizona | B21: =SUMIFS('U.S. Voters (2012)'!$C$2:$C$256,'U.S. Voters (2012)'!$A$2:$A$256,$A21) -> 4863000 | C21: =SUMIFS('U.S. Voters (2012)'!$D$2:$D$256,'U.S. Voters (2012)'!$A$2:$A$256,$A21) -> 4315000 | D21: =SUMIFS('U.S. Voters (2012)'!$E$2:$E$256,'U.S. Voters (2012)'!$A$2:$A$256,$A21) -> 2811000 | E21: =SUMIFS('U.S. Voters (2012)'!$F$2:$F$256,'U.S. Voters (2012)'!$A$2:$A$256,$A21) -> 2412000 | F21: =D21/C21 -> 0.65144844 | G21: =E21/D21 -> 0.85805763 | H21: =E21/B21 -> 0.49599013 | I21: =C21-D21 -> 1504000 | J21: =I21/C21 -> 0.34855156 | K21: =COUNTIF($G$19:$G$69,">"&G21)+COUNTIF($G$19:G21,G21) -> 34 | L21: =COUNTIF($I$19:$I$69,">"&I21)+COUNTIF($I$19:I21,I21) -> 11 | M21: =COUNTIF($E$19:$E$69,">"&E21)+COUNTIF($E$19:E21,E21) -> 22 | N21: =COUNTIF($H$19:$H$69,">"&H21)+COUNTIF($H$19:H21,H21) -> 47 | O21: =IF(F21>=MEDIAN($F$19:$F$69),G21,2) -> 2 | P21: =COUNTIF($O$19:$O$69,"<"&O21)+COUNTIF($O$19:O21,O21) -> 28 | R21: =INDEX($A$19:$A$69,MATCH(3,$K$19:$K$69,0)) -> Minnesota | S21: =INDEX($G$19:$G$69,MATCH(3,$K$19:$K$69,0)) -> 0.9267423 | U21: =INDEX($A$19:$A$69,MATCH(3,$L$19:$L$69,0)) -> Florida | V21: =INDEX($I$19:$I$69,MATCH(3,$L$19:$L$69,0)) -> 4224000 | X21: =INDEX($A$19:$A$69,MATCH(3,$M$19:$M$69,0)) -> Florida | Y21: =INDEX($E$19:$E$69,MATCH(3,$M$19:$M$69,0)) -> 8107000 | Z21: =INDEX($B$19:$B$69,MATCH(3,$M$19:$M$69,0)) -> 15033000 | AB21: =INDEX($A$19:$A$69,MATCH(3,$N$19:$N$69,0)) -> Minnesota | AC21: =INDEX($H$19:$H$69,MATCH(3,$N$19:$N$69,0)) -> 0.7052294 | AE21: =INDEX($A$19:$A$69,MATCH(3,$P$19:$P$69,0)) -> Alabama | AF21: =INDEX($F$19:$F$69,MATCH(3,$P$19:$P$69,0)) -> 0.7341954 | AG21: =INDEX($G$19:$G$69,MATCH(3,$P$19:$P$69,0)) -> 0.84305284
A22: Arkansas | B22: =SUMIFS('U.S. Voters (2012)'!$C$2:$C$256,'U.S. Voters (2012)'!$A$2:$A$256,$A22) -> 2198000 | C22: =SUMIFS('U.S. Voters (2012)'!$D$2:$D$256,'U.S. Voters (2012)'!$A$2:$A$256,$A22) -> 2110000 | D22: =SUMIFS('U.S. Voters (2012)'!$E$2:$E$256,'U.S. Voters (2012)'!$A$2:$A$256,$A22) -> 1376000 | E22: =SUMIFS('U.S. Voters (2012)'!$F$2:$F$256,'U.S. Voters (2012)'!$A$2:$A$256,$A22) -> 1124000 | F22: =D22/C22 -> 0.6521327 | G22: =E22/D22 -> 0.81686047 | H22: =E22/B22 -> 0.51137398 | I22: =C22-D22 -> 734000 | J22: =I22/C22 -> 0.3478673 | K22: =COUNTIF($G$19:$G$69,">"&G22)+COUNTIF($G$19:G22,G22) -> 46 | L22: =COUNTIF($I$19:$I$69,">"&I22)+COUNTIF($I$19:I22,I22) -> 29 | M22: =COUNTIF($E$19:$E$69,">"&E22)+COUNTIF($E$19:E22,E22) -> 33 | N22: =COUNTIF($H$19:$H$69,">"&H22)+COUNTIF($H$19:H22,H22) -> 44 | O22: =IF(F22>=MEDIAN($F$19:$F$69),G22,2) -> 2 | P22: =COUNTIF($O$19:$O$69,"<"&O22)+COUNTIF($O$19:O22,O22) -> 29 | R22: =INDEX($A$19:$A$69,MATCH(4,$K$19:$K$69,0)) -> Wyoming | S22: =INDEX($G$19:$G$69,MATCH(4,$K$19:$K$69,0)) -> 0.92164179 | U22: =INDEX($A$19:$A$69,MATCH(4,$L$19:$L$69,0)) -> New York | V22: =INDEX($I$19:$I$69,MATCH(4,$L$19:$L$69,0)) -> 4195000 | X22: =INDEX($A$19:$A$69,MATCH(4,$M$19:$M$69,0)) -> New York | Y22: =INDEX($E$19:$E$69,MATCH(4,$M$19:$M$69,0)) -> 7676000 | Z22: =INDEX($B$19:$B$69,MATCH(4,$M$19:$M$69,0)) -> 15066000 | AB22: =INDEX($A$19:$A$69,MATCH(4,$N$19:$N$69,0)) -> District Of Columbia | AC22: =INDEX($H$19:$H$69,MATCH(4,$N$19:$N$69,0)) -> 0.67891683 | AE22: =INDEX($A$19:$A$69,MATCH(4,$P$19:$P$69,0)) -> New Jersey | AF22: =INDEX($F$19:$F$69,MATCH(4,$P$19:$P$69,0)) -> 0.729634 | AG22: =INDEX($G$19:$G$69,MATCH(4,$P$19:$P$69,0)) -> 0.84835876
A23: California | B23: =SUMIFS('U.S. Voters (2012)'!$C$2:$C$256,'U.S. Voters (2012)'!$A$2:$A$256,$A23) -> 28358000 | C23: =SUMIFS('U.S. Voters (2012)'!$D$2:$D$256,'U.S. Voters (2012)'!$A$2:$A$256,$A23) -> 23418000 | D23: =SUMIFS('U.S. Voters (2012)'!$E$2:$E$256,'U.S. Voters (2012)'!$A$2:$A$256,$A23) -> 15356000 | E23: =SUMIFS('U.S. Voters (2012)'!$F$2:$F$256,'U.S. Voters (2012)'!$A$2:$A$256,$A23) -> 13463000 | F23: =D23/C23 -> 0.6557349 | G23: =E23/D23 -> 0.87672571 | H23: =E23/B23 -> 0.47475139 | I23: =C23-D23 -> 8062000 | J23: =I23/C23 -> 0.3442651 | K23: =COUNTIF($G$19:$G$69,">"&G23)+COUNTIF($G$19:G23,G23) -> 27 | L23: =COUNTIF($I$19:$I$69,">"&I23)+COUNTIF($I$19:I23,I23) -> 1 | M23: =COUNTIF($E$19:$E$69,">"&E23)+COUNTIF($E$19:E23,E23) -> 1 | N23: =COUNTIF($H$19:$H$69,">"&H23)+COUNTIF($H$19:H23,H23) -> 49 | O23: =IF(F23>=MEDIAN($F$19:$F$69),G23,2) -> 2 | P23: =COUNTIF($O$19:$O$69,"<"&O23)+COUNTIF($O$19:O23,O23) -> 30 | R23: =INDEX($A$19:$A$69,MATCH(5,$K$19:$K$69,0)) -> Delaware | S23: =INDEX($G$19:$G$69,MATCH(5,$K$19:$K$69,0)) -> 0.91684435 | U23: =INDEX($A$19:$A$69,MATCH(5,$L$19:$L$69,0)) -> Pennsylvania | V23: =INDEX($I$19:$I$69,MATCH(5,$L$19:$L$69,0)) -> 2657000 | X23: =INDEX($A$19:$A$69,MATCH(5,$M$19:$M$69,0)) -> Pennsylvania | Y23: =INDEX($E$19:$E$69,MATCH(5,$M$19:$M$69,0)) -> 5824000 | Z23: =INDEX($B$19:$B$69,MATCH(5,$M$19:$M$69,0)) -> 9848000 | AB23: =INDEX($A$19:$A$69,MATCH(5,$N$19:$N$69,0)) -> Maine | AC23: =INDEX($H$19:$H$69,MATCH(5,$N$19:$N$69,0)) -> 0.67146974 | AE23: =INDEX($A$19:$A$69,MATCH(5,$P$19:$P$69,0)) -> Rhode Island | AF23: =INDEX($F$19:$F$69,MATCH(5,$P$19:$P$69,0)) -> 0.73501997 | AG23: =INDEX($G$19:$G$69,MATCH(5,$P$19:$P$69,0)) -> 0.84963768
A24: Colorado | B24: =SUMIFS('U.S. Voters (2012)'!$C$2:$C$256,'U.S. Voters (2012)'!$A$2:$A$256,$A24) -> 3817000 | C24: =SUMIFS('U.S. Voters (2012)'!$D$2:$D$256,'U.S. Voters (2012)'!$A$2:$A$256,$A24) -> 3543000 | D24: =SUMIFS('U.S. Voters (2012)'!$E$2:$E$256,'U.S. Voters (2012)'!$A$2:$A$256,$A24) -> 2635000 | E24: =SUMIFS('U.S. Voters (2012)'!$F$2:$F$256,'U.S. Voters (2012)'!$A$2:$A$256,$A24) -> 2495000 | F24: =D24/C24 -> 0.74372001 | G24: =E24/D24 -> 0.94686907 | H24: =E24/B24 -> 0.6536547 | I24: =C24-D24 -> 908000 | J24: =I24/C24 -> 0.25627999 | K24: =COUNTIF($G$19:$G$69,">"&G24)+COUNTIF($G$19:G24,G24) -> 1 | L24: =COUNTIF($I$19:$I$69,">"&I24)+COUNTIF($I$19:I24,I24) -> 23 | M24: =COUNTIF($E$19:$E$69,">"&E24)+COUNTIF($E$19:E24,E24) -> 21 | N24: =COUNTIF($H$19:$H$69,">"&H24)+COUNTIF($H$19:H24,H24) -> 9 | O24: =IF(F24>=MEDIAN($F$19:$F$69),G24,2) -> 0.94686907 | P24: =COUNTIF($O$19:$O$69,"<"&O24)+COUNTIF($O$19:O24,O24) -> 26 | R24: =INDEX($A$19:$A$69,MATCH(6,$K$19:$K$69,0)) -> New Hampshire | S24: =INDEX($G$19:$G$69,MATCH(6,$K$19:$K$69,0)) -> 0.91489362 | U24: =INDEX($A$19:$A$69,MATCH(6,$L$19:$L$69,0)) -> Ohio | V24: =INDEX($I$19:$I$69,MATCH(6,$L$19:$L$69,0)) -> 2474000 | X24: =INDEX($A$19:$A$69,MATCH(6,$M$19:$M$69,0)) -> Illinois | Y24: =INDEX($E$19:$E$69,MATCH(6,$M$19:$M$69,0)) -> 5428000 | Z24: =INDEX($B$19:$B$69,MATCH(6,$M$19:$M$69,0)) -> 9650000 | AB24: =INDEX($A$19:$A$69,MATCH(6,$N$19:$N$69,0)) -> New Hampshire | AC24: =INDEX($H$19:$H$69,MATCH(6,$N$19:$N$69,0)) -> 0.6686103 | AE24: =INDEX($A$19:$A$69,MATCH(6,$P$19:$P$69,0)) -> Kansas | AF24: =INDEX($F$19:$F$69,MATCH(6,$P$19:$P$69,0)) -> 0.74316109 | AG24: =INDEX($G$19:$G$69,MATCH(6,$P$19:$P$69,0)) -> 0.85139741
A25: Connecticut | B25: =SUMIFS('U.S. Voters (2012)'!$C$2:$C$256,'U.S. Voters (2012)'!$A$2:$A$256,$A25) -> 2726000 | C25: =SUMIFS('U.S. Voters (2012)'!$D$2:$D$256,'U.S. Voters (2012)'!$A$2:$A$256,$A25) -> 2500000 | D25: =SUMIFS('U.S. Voters (2012)'!$E$2:$E$256,'U.S. Voters (2012)'!$A$2:$A$256,$A25) -> 1761000 | E25: =SUMIFS('U.S. Voters (2012)'!$F$2:$F$256,'U.S. Voters (2012)'!$A$2:$A$256,$A25) -> 1569000 | F25: =D25/C25 -> 0.7044 | G25: =E25/D25 -> 0.89097104 | H25: =E25/B25 -> 0.5755686 | I25: =C25-D25 -> 739000 | J25: =I25/C25 -> 0.2956 | K25: =COUNTIF($G$19:$G$69,">"&G25)+COUNTIF($G$19:G25,G25) -> 18 | L25: =COUNTIF($I$19:$I$69,">"&I25)+COUNTIF($I$19:I25,I25) -> 28 | M25: =COUNTIF($E$19:$E$69,">"&E25)+COUNTIF($E$19:E25,E25) -> 29 | N25: =COUNTIF($H$19:$H$69,">"&H25)+COUNTIF($H$19:H25,H25) -> 34 | O25: =IF(F25>=MEDIAN($F$19:$F$69),G25,2) -> 2 | P25: =COUNTIF($O$19:$O$69,"<"&O25)+COUNTIF($O$19:O25,O25) -> 31 | R25: =INDEX($A$19:$A$69,MATCH(7,$K$19:$K$69,0)) -> Idaho | S25: =INDEX($G$19:$G$69,MATCH(7,$K$19:$K$69,0)) -> 0.91397849 | U25: =INDEX($A$19:$A$69,MATCH(7,$L$19:$L$69,0)) -> Illinois | V25: =INDEX($I$19:$I$69,MATCH(7,$L$19:$L$69,0)) -> 2407000 | X25: =INDEX($A$19:$A$69,MATCH(7,$M$19:$M$69,0)) -> Ohio | Y25: =INDEX($E$19:$E$69,MATCH(7,$M$19:$M$69,0)) -> 5395000 | Z25: =INDEX($B$19:$B$69,MATCH(7,$M$19:$M$69,0)) -> 8751000 | AB25: =INDEX($A$19:$A$69,MATCH(7,$N$19:$N$69,0)) -> Iowa | AC25: =INDEX($H$19:$H$69,MATCH(7,$N$19:$N$69,0)) -> 0.66752911 | AE25: =INDEX($A$19:$A$69,MATCH(7,$P$19:$P$69,0)) -> North Dakota | AF25: =INDEX($F$19:$F$69,MATCH(7,$P$19:$P$69,0)) -> 0.74563107 | AG25: =INDEX($G$19:$G$69,MATCH(7,$P$19:$P$69,0)) -> 0.85416667
A26: Delaware | B26: =SUMIFS('U.S. Voters (2012)'!$C$2:$C$256,'U.S. Voters (2012)'!$A$2:$A$256,$A26) -> 693000 | C26: =SUMIFS('U.S. Voters (2012)'!$D$2:$D$256,'U.S. Voters (2012)'!$A$2:$A$256,$A26) -> 642000 | D26: =SUMIFS('U.S. Voters (2012)'!$E$2:$E$256,'U.S. Voters (2012)'!$A$2:$A$256,$A26) -> 469000 | E26: =SUMIFS('U.S. Voters (2012)'!$F$2:$F$256,'U.S. Voters (2012)'!$A$2:$A$256,$A26) -> 430000 | F26: =D26/C26 -> 0.7305296 | G26: =E26/D26 -> 0.91684435 | H26: =E26/B26 -> 0.62049062 | I26: =C26-D26 -> 173000 | J26: =I26/C26 -> 0.2694704 | K26: =COUNTIF($G$19:$G$69,">"&G26)+COUNTIF($G$19:G26,G26) -> 5 | L26: =COUNTIF($I$19:$I$69,">"&I26)+COUNTIF($I$19:I26,I26) -> 45 | M26: =COUNTIF($E$19:$E$69,">"&E26)+COUNTIF($E$19:E26,E26) -> 45 | N26: =COUNTIF($H$19:$H$69,">"&H26)+COUNTIF($H$19:H26,H26) -> 18 | O26: =IF(F26>=MEDIAN($F$19:$F$69),G26,2) -> 0.91684435 | P26: =COUNTIF($O$19:$O$69,"<"&O26)+COUNTIF($O$19:O26,O26) -> 23 | R26: =INDEX($A$19:$A$69,MATCH(8,$K$19:$K$69,0)) -> District Of Columbia | S26: =INDEX($G$19:$G$69,MATCH(8,$K$19:$K$69,0)) -> 0.91168831 | U26: =INDEX($A$19:$A$69,MATCH(8,$L$19:$L$69,0)) -> Georgia | V26: =INDEX($I$19:$I$69,MATCH(8,$L$19:$L$69,0)) -> 1972000 | X26: =INDEX($A$19:$A$69,MATCH(8,$M$19:$M$69,0)) -> Michigan | Y26: =INDEX($E$19:$E$69,MATCH(8,$M$19:$M$69,0)) -> 4831000 | Z26: =INDEX($B$19:$B$69,MATCH(8,$M$19:$M$69,0)) -> 7496000 | AB26: =INDEX($A$19:$A$69,MATCH(8,$N$19:$N$69,0)) -> Massachusetts | AC26: =INDEX($H$19:$H$69,MATCH(8,$N$19:$N$69,0)) -> 0.65415861 | AE26: =INDEX($A$19:$A$69,MATCH(8,$P$19:$P$69,0)) -> Michigan | AF26: =INDEX($F$19:$F$69,MATCH(8,$P$19:$P$69,0)) -> 0.77767017 | AG26: =INDEX($G$19:$G$69,MATCH(8,$P$19:$P$69,0)) -> 0.85945561
A27: District Of Columbia | B27: =SUMIFS('U.S. Voters (2012)'!$C$2:$C$256,'U.S. Voters (2012)'!$A$2:$A$256,$A27) -> 517000 | C27: =SUMIFS('U.S. Voters (2012)'!$D$2:$D$256,'U.S. Voters (2012)'!$A$2:$A$256,$A27) -> 461000 | D27: =SUMIFS('U.S. Voters (2012)'!$E$2:$E$256,'U.S. Voters (2012)'!$A$2:$A$256,$A27) -> 385000 | E27: =SUMIFS('U.S. Voters (2012)'!$F$2:$F$256,'U.S. Voters (2012)'!$A$2:$A$256,$A27) -> 351000 | F27: =D27/C27 -> 0.835141 | G27: =E27/D27 -> 0.91168831 | H27: =E27/B27 -> 0.67891683 | I27: =C27-D27 -> 76000 | J27: =I27/C27 -> 0.164859 | K27: =COUNTIF($G$19:$G$69,">"&G27)+COUNTIF($G$19:G27,G27) -> 8 | L27: =COUNTIF($I$19:$I$69,">"&I27)+COUNTIF($I$19:I27,I27) -> 51 | M27: =COUNTIF($E$19:$E$69,">"&E27)+COUNTIF($E$19:E27,E27) -> 47 | N27: =COUNTIF($H$19:$H$69,">"&H27)+COUNTIF($H$19:H27,H27) -> 4 | O27: =IF(F27>=MEDIAN($F$19:$F$69),G27,2) -> 0.91168831 | P27: =COUNTIF($O$19:$O$69,"<"&O27)+COUNTIF($O$19:O27,O27) -> 21 | R27: =INDEX($A$19:$A$69,MATCH(9,$K$19:$K$69,0)) -> Oregon | S27: =INDEX($G$19:$G$69,MATCH(9,$K$19:$K$69,0)) -> 0.90939597 | U27: =INDEX($A$19:$A$69,MATCH(9,$L$19:$L$69,0)) -> Michigan | V27: =INDEX($I$19:$I$69,MATCH(9,$L$19:$L$69,0)) -> 1607000 | X27: =INDEX($A$19:$A$69,MATCH(9,$M$19:$M$69,0)) -> North Carolina | Y27: =INDEX($E$19:$E$69,MATCH(9,$M$19:$M$69,0)) -> 4624000 | Z27: =INDEX($B$19:$B$69,MATCH(9,$M$19:$M$69,0)) -> 7263000 | AB27: =INDEX($A$19:$A$69,MATCH(9,$N$19:$N$69,0)) -> Colorado | AC27: =INDEX($H$19:$H$69,MATCH(9,$N$19:$N$69,0)) -> 0.6536547 | AE27: =INDEX($A$19:$A$69,MATCH(9,$P$19:$P$69,0)) -> Louisiana | AF27: =INDEX($F$19:$F$69,MATCH(9,$P$19:$P$69,0)) -> 0.77122569 | AG27: =INDEX($G$19:$G$69,MATCH(9,$P$19:$P$69,0)) -> 0.86028823
A28: Florida | B28: =SUMIFS('U.S. Voters (2012)'!$C$2:$C$256,'U.S. Voters (2012)'!$A$2:$A$256,$A28) -> 15033000 | C28: =SUMIFS('U.S. Voters (2012)'!$D$2:$D$256,'U.S. Voters (2012)'!$A$2:$A$256,$A28) -> 13326000 | D28: =SUMIFS('U.S. Voters (2012)'!$E$2:$E$256,'U.S. Voters (2012)'!$A$2:$A$256,$A28) -> 9102000 | E28: =SUMIFS('U.S. Voters (2012)'!$F$2:$F$256,'U.S. Voters (2012)'!$A$2:$A$256,$A28) -> 8107000 | F28: =D28/C28 -> 0.68302566 | G28: =E28/D28 -> 0.89068337 | H28: =E28/B28 -> 0.53928025 | I28: =C28-D28 -> 4224000 | J28: =I28/C28 -> 0.31697434 | K28: =COUNTIF($G$19:$G$69,">"&G28)+COUNTIF($G$19:G28,G28) -> 19 | L28: =COUNTIF($I$19:$I$69,">"&I28)+COUNTIF($I$19:I28,I28) -> 3 | M28: =COUNTIF($E$19:$E$69,">"&E28)+COUNTIF($E$19:E28,E28) -> 3 | N28: =COUNTIF($H$19:$H$69,">"&H28)+COUNTIF($H$19:H28,H28) -> 40 | O28: =IF(F28>=MEDIAN($F$19:$F$69),G28,2) -> 2 | P28: =COUNTIF($O$19:$O$69,"<"&O28)+COUNTIF($O$19:O28,O28) -> 32 | R28: =INDEX($A$19:$A$69,MATCH(10,$K$19:$K$69,0)) -> Maryland | S28: =INDEX($G$19:$G$69,MATCH(10,$K$19:$K$69,0)) -> 0.90373961 | U28: =INDEX($A$19:$A$69,MATCH(10,$L$19:$L$69,0)) -> New Jersey | V28: =INDEX($I$19:$I$69,MATCH(10,$L$19:$L$69,0)) -> 1603000 | X28: =INDEX($A$19:$A$69,MATCH(10,$M$19:$M$69,0)) -> Georgia | Y28: =INDEX($E$19:$E$69,MATCH(10,$M$19:$M$69,0)) -> 4168000 | Z28: =INDEX($B$19:$B$69,MATCH(10,$M$19:$M$69,0)) -> 7178000 | AB28: =INDEX($A$19:$A$69,MATCH(10,$N$19:$N$69,0)) -> Louisiana | AC28: =INDEX($H$19:$H$69,MATCH(10,$N$19:$N$69,0)) -> 0.64728916 | AE28: =INDEX($A$19:$A$69,MATCH(10,$P$19:$P$69,0)) -> Vermont | AF28: =INDEX($F$19:$F$69,MATCH(10,$P$19:$P$69,0)) -> 0.73100616 | AG28: =INDEX($G$19:$G$69,MATCH(10,$P$19:$P$69,0)) -> 0.86235955
A29: Georgia | B29: =SUMIFS('U.S. Voters (2012)'!$C$2:$C$256,'U.S. Voters (2012)'!$A$2:$A$256,$A29) -> 7178000 | C29: =SUMIFS('U.S. Voters (2012)'!$D$2:$D$256,'U.S. Voters (2012)'!$A$2:$A$256,$A29) -> 6738000 | D29: =SUMIFS('U.S. Voters (2012)'!$E$2:$E$256,'U.S. Voters (2012)'!$A$2:$A$256,$A29) -> 4766000 | E29: =SUMIFS('U.S. Voters (2012)'!$F$2:$F$256,'U.S. Voters (2012)'!$A$2:$A$256,$A29) -> 4168000 | F29: =D29/C29 -> 0.70733155 | G29: =E29/D29 -> 0.87452791 | H29: =E29/B29 -> 0.58066314 | I29: =C29-D29 -> 1972000 | J29: =I29/C29 -> 0.29266845 | K29: =COUNTIF($G$19:$G$69,">"&G29)+COUNTIF($G$19:G29,G29) -> 28 | L29: =COUNTIF($I$19:$I$69,">"&I29)+COUNTIF($I$19:I29,I29) -> 8 | M29: =COUNTIF($E$19:$E$69,">"&E29)+COUNTIF($E$19:E29,E29) -> 10 | N29: =COUNTIF($H$19:$H$69,">"&H29)+COUNTIF($H$19:H29,H29) -> 30 | O29: =IF(F29>=MEDIAN($F$19:$F$69),G29,2) -> 2 | P29: =COUNTIF($O$19:$O$69,"<"&O29)+COUNTIF($O$19:O29,O29) -> 33
A30: Hawaii | B30: =SUMIFS('U.S. Voters (2012)'!$C$2:$C$256,'U.S. Voters (2012)'!$A$2:$A$256,$A30) -> 1012000 | C30: =SUMIFS('U.S. Voters (2012)'!$D$2:$D$256,'U.S. Voters (2012)'!$A$2:$A$256,$A30) -> 930000 | D30: =SUMIFS('U.S. Voters (2012)'!$E$2:$E$256,'U.S. Voters (2012)'!$A$2:$A$256,$A30) -> 547000 | E30: =SUMIFS('U.S. Voters (2012)'!$F$2:$F$256,'U.S. Voters (2012)'!$A$2:$A$256,$A30) -> 481000 | F30: =D30/C30 -> 0.58817204 | G30: =E30/D30 -> 0.87934186 | H30: =E30/B30 -> 0.47529644 | I30: =C30-D30 -> 383000 | J30: =I30/C30 -> 0.41182796 | K30: =COUNTIF($G$19:$G$69,">"&G30)+COUNTIF($G$19:G30,G30) -> 26 | L30: =COUNTIF($I$19:$I$69,">"&I30)+COUNTIF($I$19:I30,I30) -> 38 | M30: =COUNTIF($E$19:$E$69,">"&E30)+COUNTIF($E$19:E30,E30) -> 43 | N30: =COUNTIF($H$19:$H$69,">"&H30)+COUNTIF($H$19:H30,H30) -> 48 | O30: =IF(F30>=MEDIAN($F$19:$F$69),G30,2) -> 2 | P30: =COUNTIF($O$19:$O$69,"<"&O30)+COUNTIF($O$19:O30,O30) -> 34
A31: Idaho | B31: =SUMIFS('U.S. Voters (2012)'!$C$2:$C$256,'U.S. Voters (2012)'!$A$2:$A$256,$A31) -> 1129000 | C31: =SUMIFS('U.S. Voters (2012)'!$D$2:$D$256,'U.S. Voters (2012)'!$A$2:$A$256,$A31) -> 1064000 | D31: =SUMIFS('U.S. Voters (2012)'!$E$2:$E$256,'U.S. Voters (2012)'!$A$2:$A$256,$A31) -> 744000 | E31: =SUMIFS('U.S. Voters (2012)'!$F$2:$F$256,'U.S. Voters (2012)'!$A$2:$A$256,$A31) -> 680000 | F31: =D31/C31 -> 0.69924812 | G31: =E31/D31 -> 0.91397849 | H31: =E31/B31 -> 0.60230292 | I31: =C31-D31 -> 320000 | J31: =I31/C31 -> 0.30075188 | K31: =COUNTIF($G$19:$G$69,">"&G31)+COUNTIF($G$19:G31,G31) -> 7 | L31: =COUNTIF($I$19:$I$69,">"&I31)+COUNTIF($I$19:I31,I31) -> 40 | M31: =COUNTIF($E$19:$E$69,">"&E31)+COUNTIF($E$19:E31,E31) -> 41 | N31: =COUNTIF($H$19:$H$69,">"&H31)+COUNTIF($H$19:H31,H31) -> 23 | O31: =IF(F31>=MEDIAN($F$19:$F$69),G31,2) -> 2 | P31: =COUNTIF($O$19:$O$69,"<"&O31)+COUNTIF($O$19:O31,O31) -> 35 | R31: Row Labels | S31: Sum of Registration Rate | T31: Sum of Turnout Rate | U31: Sum of Voter Penetration
A32: Illinois | B32: =SUMIFS('U.S. Voters (2012)'!$C$2:$C$256,'U.S. Voters (2012)'!$A$2:$A$256,$A32) -> 9650000 | C32: =SUMIFS('U.S. Voters (2012)'!$D$2:$D$256,'U.S. Voters (2012)'!$A$2:$A$256,$A32) -> 8831000 | D32: =SUMIFS('U.S. Voters (2012)'!$E$2:$E$256,'U.S. Voters (2012)'!$A$2:$A$256,$A32) -> 6424000 | E32: =SUMIFS('U.S. Voters (2012)'!$F$2:$F$256,'U.S. Voters (2012)'!$A$2:$A$256,$A32) -> 5428000 | F32: =D32/C32 -> 0.72743744 | G32: =E32/D32 -> 0.84495641 | H32: =E32/B32 -> 0.56248705 | I32: =C32-D32 -> 2407000 | J32: =I32/C32 -> 0.27256256 | K32: =COUNTIF($G$19:$G$69,">"&G32)+COUNTIF($G$19:G32,G32) -> 41 | L32: =COUNTIF($I$19:$I$69,">"&I32)+COUNTIF($I$19:I32,I32) -> 7 | M32: =COUNTIF($E$19:$E$69,">"&E32)+COUNTIF($E$19:E32,E32) -> 6 | N32: =COUNTIF($H$19:$H$69,">"&H32)+COUNTIF($H$19:H32,H32) -> 37 | O32: =IF(F32>=MEDIAN($F$19:$F$69),G32,2) -> 2 | P32: =COUNTIF($O$19:$O$69,"<"&O32)+COUNTIF($O$19:O32,O32) -> 36 | R32: 18 to 24 | S32: 0.5362603 | T32: 0.76867339 | U32: 0.3798735
A33: Indiana | B33: =SUMIFS('U.S. Voters (2012)'!$C$2:$C$256,'U.S. Voters (2012)'!$A$2:$A$256,$A33) -> 4853000 | C33: =SUMIFS('U.S. Voters (2012)'!$D$2:$D$256,'U.S. Voters (2012)'!$A$2:$A$256,$A33) -> 4724000 | D33: =SUMIFS('U.S. Voters (2012)'!$E$2:$E$256,'U.S. Voters (2012)'!$A$2:$A$256,$A33) -> 3270000 | E33: =SUMIFS('U.S. Voters (2012)'!$F$2:$F$256,'U.S. Voters (2012)'!$A$2:$A$256,$A33) -> 2801000 | F33: =D33/C33 -> 0.69220999 | G33: =E33/D33 -> 0.85657492 | H33: =E33/B33 -> 0.57716876 | I33: =C33-D33 -> 1454000 | J33: =I33/C33 -> 0.30779001 | K33: =COUNTIF($G$19:$G$69,">"&G33)+COUNTIF($G$19:G33,G33) -> 36 | L33: =COUNTIF($I$19:$I$69,">"&I33)+COUNTIF($I$19:I33,I33) -> 13 | M33: =COUNTIF($E$19:$E$69,">"&E33)+COUNTIF($E$19:E33,E33) -> 18 | N33: =COUNTIF($H$19:$H$69,">"&H33)+COUNTIF($H$19:H33,H33) -> 32 | O33: =IF(F33>=MEDIAN($F$19:$F$69),G33,2) -> 2 | P33: =COUNTIF($O$19:$O$69,"<"&O33)+COUNTIF($O$19:O33,O33) -> 37 | R33: 25 to 34 | S33: 0.66065287 | T33: 0.80977983 | U33: 0.46124681
A34: Iowa | B34: =SUMIFS('U.S. Voters (2012)'!$C$2:$C$256,'U.S. Voters (2012)'!$A$2:$A$256,$A34) -> 2319000 | C34: =SUMIFS('U.S. Voters (2012)'!$D$2:$D$256,'U.S. Voters (2012)'!$A$2:$A$256,$A34) -> 2232000 | D34: =SUMIFS('U.S. Voters (2012)'!$E$2:$E$256,'U.S. Voters (2012)'!$A$2:$A$256,$A34) -> 1745000 | E34: =SUMIFS('U.S. Voters (2012)'!$F$2:$F$256,'U.S. Voters (2012)'!$A$2:$A$256,$A34) -> 1548000 | F34: =D34/C34 -> 0.78181004 | G34: =E34/D34 -> 0.88710602 | H34: =E34/B34 -> 0.66752911 | I34: =C34-D34 -> 487000 | J34: =I34/C34 -> 0.21818996 | K34: =COUNTIF($G$19:$G$69,">"&G34)+COUNTIF($G$19:G34,G34) -> 22 | L34: =COUNTIF($I$19:$I$69,">"&I34)+COUNTIF($I$19:I34,I34) -> 34 | M34: =COUNTIF($E$19:$E$69,">"&E34)+COUNTIF($E$19:E34,E34) -> 30 | N34: =COUNTIF($H$19:$H$69,">"&H34)+COUNTIF($H$19:H34,H34) -> 7 | O34: =IF(F34>=MEDIAN($F$19:$F$69),G34,2) -> 0.88710602 | P34: =COUNTIF($O$19:$O$69,"<"&O34)+COUNTIF($O$19:O34,O34) -> 14 | R34: 35 to 44 | S34: 0.71376875 | T34: 0.85718374 | U34: 0.52909853
A35: Kansas | B35: =SUMIFS('U.S. Voters (2012)'!$C$2:$C$256,'U.S. Voters (2012)'!$A$2:$A$256,$A35) -> 2120000 | C35: =SUMIFS('U.S. Voters (2012)'!$D$2:$D$256,'U.S. Voters (2012)'!$A$2:$A$256,$A35) -> 1974000 | D35: =SUMIFS('U.S. Voters (2012)'!$E$2:$E$256,'U.S. Voters (2012)'!$A$2:$A$256,$A35) -> 1467000 | E35: =SUMIFS('U.S. Voters (2012)'!$F$2:$F$256,'U.S. Voters (2012)'!$A$2:$A$256,$A35) -> 1249000 | F35: =D35/C35 -> 0.74316109 | G35: =E35/D35 -> 0.85139741 | H35: =E35/B35 -> 0.58915094 | I35: =C35-D35 -> 507000 | J35: =I35/C35 -> 0.25683891 | K35: =COUNTIF($G$19:$G$69,">"&G35)+COUNTIF($G$19:G35,G35) -> 38 | L35: =COUNTIF($I$19:$I$69,">"&I35)+COUNTIF($I$19:I35,I35) -> 33 | M35: =COUNTIF($E$19:$E$69,">"&E35)+COUNTIF($E$19:E35,E35) -> 32 | N35: =COUNTIF($H$19:$H$69,">"&H35)+COUNTIF($H$19:H35,H35) -> 27 | O35: =IF(F35>=MEDIAN($F$19:$F$69),G35,2) -> 0.85139741 | P35: =COUNTIF($O$19:$O$69,"<"&O35)+COUNTIF($O$19:O35,O35) -> 6 | R35: 45 to 64 | S35: 0.75412638 | T35: 0.8999256 | U35: 0.63364805
A36: Kentucky | B36: =SUMIFS('U.S. Voters (2012)'!$C$2:$C$256,'U.S. Voters (2012)'!$A$2:$A$256,$A36) -> 3292000 | C36: =SUMIFS('U.S. Voters (2012)'!$D$2:$D$256,'U.S. Voters (2012)'!$A$2:$A$256,$A36) -> 3193000 | D36: =SUMIFS('U.S. Voters (2012)'!$E$2:$E$256,'U.S. Voters (2012)'!$A$2:$A$256,$A36) -> 2303000 | E36: =SUMIFS('U.S. Voters (2012)'!$F$2:$F$256,'U.S. Voters (2012)'!$A$2:$A$256,$A36) -> 1895000 | F36: =D36/C36 -> 0.72126527 | G36: =E36/D36 -> 0.82283977 | H36: =E36/B36 -> 0.57563791 | I36: =C36-D36 -> 890000 | J36: =I36/C36 -> 0.27873473 | K36: =COUNTIF($G$19:$G$69,">"&G36)+COUNTIF($G$19:G36,G36) -> 44 | L36: =COUNTIF($I$19:$I$69,">"&I36)+COUNTIF($I$19:I36,I36) -> 25 | M36: =COUNTIF($E$19:$E$69,">"&E36)+COUNTIF($E$19:E36,E36) -> 27 | N36: =COUNTIF($H$19:$H$69,">"&H36)+COUNTIF($H$19:H36,H36) -> 33 | O36: =IF(F36>=MEDIAN($F$19:$F$69),G36,2) -> 2 | P36: =COUNTIF($O$19:$O$69,"<"&O36)+COUNTIF($O$19:O36,O36) -> 38 | R36: 65+ | S36: 0.7942041 | T36: 0.90671356 | U36: 0.69729971
A37: Louisiana | B37: =SUMIFS('U.S. Voters (2012)'!$C$2:$C$256,'U.S. Voters (2012)'!$A$2:$A$256,$A37) -> 3320000 | C37: =SUMIFS('U.S. Voters (2012)'!$D$2:$D$256,'U.S. Voters (2012)'!$A$2:$A$256,$A37) -> 3239000 | D37: =SUMIFS('U.S. Voters (2012)'!$E$2:$E$256,'U.S. Voters (2012)'!$A$2:$A$256,$A37) -> 2498000 | E37: =SUMIFS('U.S. Voters (2012)'!$F$2:$F$256,'U.S. Voters (2012)'!$A$2:$A$256,$A37) -> 2149000 | F37: =D37/C37 -> 0.77122569 | G37: =E37/D37 -> 0.86028823 | H37: =E37/B37 -> 0.64728916 | I37: =C37-D37 -> 741000 | J37: =I37/C37 -> 0.22877431 | K37: =COUNTIF($G$19:$G$69,">"&G37)+COUNTIF($G$19:G37,G37) -> 32 | L37: =COUNTIF($I$19:$I$69,">"&I37)+COUNTIF($I$19:I37,I37) -> 27 | M37: =COUNTIF($E$19:$E$69,">"&E37)+COUNTIF($E$19:E37,E37) -> 25 | N37: =COUNTIF($H$19:$H$69,">"&H37)+COUNTIF($H$19:H37,H37) -> 10 | O37: =IF(F37>=MEDIAN($F$19:$F$69),G37,2) -> 0.86028823 | P37: =COUNTIF($O$19:$O$69,"<"&O37)+COUNTIF($O$19:O37,O37) -> 9 | R37: Total | S37: 0.71205802 | T37: 0.86809922 | U37: 0.56515437
A38: Maine | B38: =SUMIFS('U.S. Voters (2012)'!$C$2:$C$256,'U.S. Voters (2012)'!$A$2:$A$256,$A38) -> 1041000 | C38: =SUMIFS('U.S. Voters (2012)'!$D$2:$D$256,'U.S. Voters (2012)'!$A$2:$A$256,$A38) -> 1020000 | D38: =SUMIFS('U.S. Voters (2012)'!$E$2:$E$256,'U.S. Voters (2012)'!$A$2:$A$256,$A38) -> 787000 | E38: =SUMIFS('U.S. Voters (2012)'!$F$2:$F$256,'U.S. Voters (2012)'!$A$2:$A$256,$A38) -> 699000 | F38: =D38/C38 -> 0.77156863 | G38: =E38/D38 -> 0.88818297 | H38: =E38/B38 -> 0.67146974 | I38: =C38-D38 -> 233000 | J38: =I38/C38 -> 0.22843137 | K38: =COUNTIF($G$19:$G$69,">"&G38)+COUNTIF($G$19:G38,G38) -> 20 | L38: =COUNTIF($I$19:$I$69,">"&I38)+COUNTIF($I$19:I38,I38) -> 42 | M38: =COUNTIF($E$19:$E$69,">"&E38)+COUNTIF($E$19:E38,E38) -> 38 | N38: =COUNTIF($H$19:$H$69,">"&H38)+COUNTIF($H$19:H38,H38) -> 5 | O38: =IF(F38>=MEDIAN($F$19:$F$69),G38,2) -> 0.88818297 | P38: =COUNTIF($O$19:$O$69,"<"&O38)+COUNTIF($O$19:O38,O38) -> 15 | R38: Grand Total | S38: 4.1710704 | T38: 5.1103754 | U38: 3.266321
A39: Maryland | B39: =SUMIFS('U.S. Voters (2012)'!$C$2:$C$256,'U.S. Voters (2012)'!$A$2:$A$256,$A39) -> 4449000 | C39: =SUMIFS('U.S. Voters (2012)'!$D$2:$D$256,'U.S. Voters (2012)'!$A$2:$A$256,$A39) -> 4006000 | D39: =SUMIFS('U.S. Voters (2012)'!$E$2:$E$256,'U.S. Voters (2012)'!$A$2:$A$256,$A39) -> 2888000 | E39: =SUMIFS('U.S. Voters (2012)'!$F$2:$F$256,'U.S. Voters (2012)'!$A$2:$A$256,$A39) -> 2610000 | F39: =D39/C39 -> 0.72091862 | G39: =E39/D39 -> 0.90373961 | H39: =E39/B39 -> 0.58664869 | I39: =C39-D39 -> 1118000 | J39: =I39/C39 -> 0.27908138 | K39: =COUNTIF($G$19:$G$69,">"&G39)+COUNTIF($G$19:G39,G39) -> 10 | L39: =COUNTIF($I$19:$I$69,">"&I39)+COUNTIF($I$19:I39,I39) -> 17 | M39: =COUNTIF($E$19:$E$69,">"&E39)+COUNTIF($E$19:E39,E39) -> 19 | N39: =COUNTIF($H$19:$H$69,">"&H39)+COUNTIF($H$19:H39,H39) -> 28 | O39: =IF(F39>=MEDIAN($F$19:$F$69),G39,2) -> 2 | P39: =COUNTIF($O$19:$O$69,"<"&O39)+COUNTIF($O$19:O39,O39) -> 39
A40: Massachusetts | B40: =SUMIFS('U.S. Voters (2012)'!$C$2:$C$256,'U.S. Voters (2012)'!$A$2:$A$256,$A40) -> 5170000 | C40: =SUMIFS('U.S. Voters (2012)'!$D$2:$D$256,'U.S. Voters (2012)'!$A$2:$A$256,$A40) -> 4773000 | D40: =SUMIFS('U.S. Voters (2012)'!$E$2:$E$256,'U.S. Voters (2012)'!$A$2:$A$256,$A40) -> 3758000 | E40: =SUMIFS('U.S. Voters (2012)'!$F$2:$F$256,'U.S. Voters (2012)'!$A$2:$A$256,$A40) -> 3382000 | F40: =D40/C40 -> 0.78734549 | G40: =E40/D40 -> 0.89994678 | H40: =E40/B40 -> 0.65415861 | I40: =C40-D40 -> 1015000 | J40: =I40/C40 -> 0.21265451 | K40: =COUNTIF($G$19:$G$69,">"&G40)+COUNTIF($G$19:G40,G40) -> 11 | L40: =COUNTIF($I$19:$I$69,">"&I40)+COUNTIF($I$19:I40,I40) -> 19 | M40: =COUNTIF($E$19:$E$69,">"&E40)+COUNTIF($E$19:E40,E40) -> 13 | N40: =COUNTIF($H$19:$H$69,">"&H40)+COUNTIF($H$19:H40,H40) -> 8 | O40: =IF(F40>=MEDIAN($F$19:$F$69),G40,2) -> 0.89994678 | P40: =COUNTIF($O$19:$O$69,"<"&O40)+COUNTIF($O$19:O40,O40) -> 19
A41: Michigan | B41: =SUMIFS('U.S. Voters (2012)'!$C$2:$C$256,'U.S. Voters (2012)'!$A$2:$A$256,$A41) -> 7496000 | C41: =SUMIFS('U.S. Voters (2012)'!$D$2:$D$256,'U.S. Voters (2012)'!$A$2:$A$256,$A41) -> 7228000 | D41: =SUMIFS('U.S. Voters (2012)'!$E$2:$E$256,'U.S. Voters (2012)'!$A$2:$A$256,$A41) -> 5621000 | E41: =SUMIFS('U.S. Voters (2012)'!$F$2:$F$256,'U.S. Voters (2012)'!$A$2:$A$256,$A41) -> 4831000 | F41: =D41/C41 -> 0.77767017 | G41: =E41/D41 -> 0.85945561 | H41: =E41/B41 -> 0.64447705 | I41: =C41-D41 -> 1607000 | J41: =I41/C41 -> 0.22232983 | K41: =COUNTIF($G$19:$G$69,">"&G41)+COUNTIF($G$19:G41,G41) -> 33 | L41: =COUNTIF($I$19:$I$69,">"&I41)+COUNTIF($I$19:I41,I41) -> 9 | M41: =COUNTIF($E$19:$E$69,">"&E41)+COUNTIF($E$19:E41,E41) -> 8 | N41: =COUNTIF($H$19:$H$69,">"&H41)+COUNTIF($H$19:H41,H41) -> 11 | O41: =IF(F41>=MEDIAN($F$19:$F$69),G41,2) -> 0.85945561 | P41: =COUNTIF($O$19:$O$69,"<"&O41)+COUNTIF($O$19:O41,O41) -> 8
A42: Minnesota | B42: =SUMIFS('U.S. Voters (2012)'!$C$2:$C$256,'U.S. Voters (2012)'!$A$2:$A$256,$A42) -> 4054000 | C42: =SUMIFS('U.S. Voters (2012)'!$D$2:$D$256,'U.S. Voters (2012)'!$A$2:$A$256,$A42) -> 3903000 | D42: =SUMIFS('U.S. Voters (2012)'!$E$2:$E$256,'U.S. Voters (2012)'!$A$2:$A$256,$A42) -> 3085000 | E42: =SUMIFS('U.S. Voters (2012)'!$F$2:$F$256,'U.S. Voters (2012)'!$A$2:$A$256,$A42) -> 2859000 | F42: =D42/C42 -> 0.79041763 | G42: =E42/D42 -> 0.9267423 | H42: =E42/B42 -> 0.7052294 | I42: =C42-D42 -> 818000 | J42: =I42/C42 -> 0.20958237 | K42: =COUNTIF($G$19:$G$69,">"&G42)+COUNTIF($G$19:G42,G42) -> 3 | L42: =COUNTIF($I$19:$I$69,">"&I42)+COUNTIF($I$19:I42,I42) -> 26 | M42: =COUNTIF($E$19:$E$69,">"&E42)+COUNTIF($E$19:E42,E42) -> 16 | N42: =COUNTIF($H$19:$H$69,">"&H42)+COUNTIF($H$19:H42,H42) -> 3 | O42: =IF(F42>=MEDIAN($F$19:$F$69),G42,2) -> 0.9267423 | P42: =COUNTIF($O$19:$O$69,"<"&O42)+COUNTIF($O$19:O42,O42) -> 24
A43: Mississippi | B43: =SUMIFS('U.S. Voters (2012)'!$C$2:$C$256,'U.S. Voters (2012)'!$A$2:$A$256,$A43) -> 2167000 | C43: =SUMIFS('U.S. Voters (2012)'!$D$2:$D$256,'U.S. Voters (2012)'!$A$2:$A$256,$A43) -> 2130000 | D43: =SUMIFS('U.S. Voters (2012)'!$E$2:$E$256,'U.S. Voters (2012)'!$A$2:$A$256,$A43) -> 1795000 | E43: =SUMIFS('U.S. Voters (2012)'!$F$2:$F$256,'U.S. Voters (2012)'!$A$2:$A$256,$A43) -> 1588000 | F43: =D43/C43 -> 0.842723 | G43: =E43/D43 -> 0.88467967 | H43: =E43/B43 -> 0.73281034 | I43: =C43-D43 -> 335000 | J43: =I43/C43 -> 0.157277 | K43: =COUNTIF($G$19:$G$69,">"&G43)+COUNTIF($G$19:G43,G43) -> 24 | L43: =COUNTIF($I$19:$I$69,">"&I43)+COUNTIF($I$19:I43,I43) -> 39 | M43: =COUNTIF($E$19:$E$69,">"&E43)+COUNTIF($E$19:E43,E43) -> 28 | N43: =COUNTIF($H$19:$H$69,">"&H43)+COUNTIF($H$19:H43,H43) -> 1 | O43: =IF(F43>=MEDIAN($F$19:$F$69),G43,2) -> 0.88467967 | P43: =COUNTIF($O$19:$O$69,"<"&O43)+COUNTIF($O$19:O43,O43) -> 13
...

Sheet U.S. Voters (2012)
A1: State | B1: Age | C1: Total Population | D1: Citizen Population | E1: Registered Voters | F1: Confirmed Voters
A2: Alabama | B2: 18 to 24 | C2: 439000 | D2: 428000 | E2: 212000 | F2: 155000
A3: Alabama | B3: 25 to 34 | C3: 576000 | D3: 535000 | E3: 359000 | F3: 271000
A4: Alabama | B4: 35 to 44 | C4: 615000 | D4: 582000 | E4: 410000 | F4: 330000
A5: Alabama | B5: 45 to 64 | C5: 1297000 | D5: 1275000 | E5: 1051000 | F5: 939000
A6: Alabama | B6: 65+ | C6: 667000 | D6: 660000 | E6: 523000 | F6: 459000
A7: Alaska | B7: 18 to 24 | C7: 63000 | D7: 61000 | E7: 31000 | F7: 20000
A8: Alaska | B8: 25 to 34 | C8: 109000 | D8: 103000 | E8: 70000 | F8: 46000
A9: Alaska | B9: 35 to 44 | C9: 86000 | D9: 80000 | E9: 60000 | F9: 50000
A10: Alaska | B10: 45 to 64 | C10: 186000 | D10: 182000 | E10: 144000 | F10: 122000
A11: Alaska | B11: 65+ | C11: 72000 | D11: 69000 | E11: 55000 | F11: 51000
A12: Arizona | B12: 18 to 24 | C12: 586000 | D12: 545000 | E12: 301000 | F12: 234000
A13: Arizona | B13: 25 to 34 | C13: 859000 | D13: 709000 | E13: 399000 | F13: 289000
... A256: Wyoming | B256: 65+ | C256: 74000 | D256: 73000 | E256: 61000 | F256: 59000

Sheet Q - Voters
A1: Voters — Dashboard Problem Statements
A2: Each dataset has 8 dashboard-ready business questions.
A4: # | B4: Problem Statement | C4: Suggested Dashboard Approach
A5: 1 | B5: How does voter turnout vary across age groups, and which age group has the highest confirmed-voter turnout rate? | C5: Suggested visuals: KPI cards, PivotTables, ranked bar charts, trend charts, conditional formatting and filters/slicers.
A6: 2 | B6: Which 10 states have the highest confirmed-voter turnout rate among registered voters? | C6: Suggested visuals: KPI cards, PivotTables, ranked bar charts, trend charts, conditional formatting and filters/slicers.
A7: 3 | B7: Which states have the largest gap between citizen population and registered voters? | C7: Suggested visuals: KPI cards, PivotTables, ranked bar charts, trend charts, conditional formatting and filters/slicers.
A8: 4 | B8: How does the registration rate (registered voters ÷ citizen population) differ by age group? | C8: Suggested visuals: KPI cards, PivotTables, ranked bar charts, trend charts, conditional formatting and filters/slicers.
A9: 5 | B9: Which states have the highest number of confirmed voters, and how does that compare with their population size? | C9: Suggested visuals: KPI cards, PivotTables, ranked bar charts, trend charts, conditional formatting and filters/slicers.
A10: 6 | B10: Which age group contributes the largest share of total confirmed voters? | C10: Suggested visuals: KPI cards, PivotTables, ranked bar charts, trend charts, conditional formatting and filters/slicers.
A11: 7 | B11: Which states show strong registration but comparatively lower confirmed-voter turnout? | C11: Suggested visuals: KPI cards, PivotTables, ranked bar charts, trend charts, conditional formatting and filters/slicers.
A12: 8 | B12: How does confirmed voter penetration (confirmed voters ÷ total population) vary across states? | C12: Suggested visuals: KPI cards, PivotTables, ranked bar charts, trend charts, conditional formatting and filters/slicers.
